Workbook

Sheet Tableau de bord
A1: Tableau de bord – avancement du TP1
A2: Tout se met à jour automatiquement quand vous changez un statut dans l'onglet Suivi.
A4: Étape | B4: Points | C4: Tâches | D4: Faites | E4: En cours | F4: À faire | G4: Avancement
A5: 1. Analyse et conception | B5: 15 | C5: =COUNTIF(Suivi!$A$6:$A$70,"E1") | D5: =COUNTIFS(Suivi!$A$6:$A$70,"E1",Suivi!$F$6:$F$70,"Fait") | E5: =COUNTIFS(Suivi!$A$6:$A$70,"E1",Suivi!$F$6:$F$70,"En cours") | F5: =COUNTIFS(Suivi!$A$6:$A$70,"E1",Suivi!$F$6:$F$70,"À faire") | G5: =IFERROR(D5/C5,0)
A6: 2. Implémentation et JSONB | B6: 20 | C6: =COUNTIF(Suivi!$A$6:$A$70,"E2") | D6: =COUNTIFS(Suivi!$A$6:$A$70,"E2",Suivi!$F$6:$F$70,"Fait") | E6: =COUNTIFS(Suivi!$A$6:$A$70,"E2",Suivi!$F$6:$F$70,"En cours") | F6: =COUNTIFS(Suivi!$A$6:$A$70,"E2",Suivi!$F$6:$F$70,"À faire") | G6: =IFERROR(D6/C6,0)
A7: 3. Fonctions avancées | B7: 20 | C7: =COUNTIF(Suivi!$A$6:$A$70,"E3") | D7: =COUNTIFS(Suivi!$A$6:$A$70,"E3",Suivi!$F$6:$F$70,"Fait") | E7: =COUNTIFS(Suivi!$A$6:$A$70,"E3",Suivi!$F$6:$F$70,"En cours") | F7: =COUNTIFS(Suivi!$A$6:$A$70,"E3",Suivi!$F$6:$F$70,"À faire") | G7: =IFERROR(D7/C7,0)
A8: 4. Requêtes et performance | B8: 20 | C8: =COUNTIF(Suivi!$A$6:$A$70,"E4") | D8: =COUNTIFS(Suivi!$A$6:$A$70,"E4",Suivi!$F$6:$F$70,"Fait") | E8: =COUNTIFS(Suivi!$A$6:$A$70,"E4",Suivi!$F$6:$F$70,"En cours") | F8: =COUNTIFS(Suivi!$A$6:$A$70,"E4",Suivi!$F$6:$F$70,"À faire") | G8: =IFERROR(D8/C8,0)
A9: 5. Application cliente | B9: 10 | C9: =COUNTIF(Suivi!$A$6:$A$70,"E5") | D9: =COUNTIFS(Suivi!$A$6:$A$70,"E5",Suivi!$F$6:$F$70,"Fait") | E9: =COUNTIFS(Suivi!$A$6:$A$70,"E5",Suivi!$F$6:$F$70,"En cours") | F9: =COUNTIFS(Suivi!$A$6:$A$70,"E5",Suivi!$F$6:$F$70,"À faire") | G9: =IFERROR(D9/C9,0)
A10: 6. Tests et reproductibilité | C10: =COUNTIF(Suivi!$A$6:$A$70,"E6") | D10: =COUNTIFS(Suivi!$A$6:$A$70,"E6",Suivi!$F$6:$F$70,"Fait") | E10: =COUNTIFS(Suivi!$A$6:$A$70,"E6",Suivi!$F$6:$F$70,"En cours") | F10: =COUNTIFS(Suivi!$A$6:$A$70,"E6",Suivi!$F$6:$F$70,"À faire") | G10: =IFERROR(D10/C10,0)
A11: 7. Base de connaissances | B11: 10 | C11: =COUNTIF(Suivi!$A$6:$A$70,"E7") | D11: =COUNTIFS(Suivi!$A$6:$A$70,"E7",Suivi!$F$6:$F$70,"Fait") | E11: =COUNTIFS(Suivi!$A$6:$A$70,"E7",Suivi!$F$6:$F$70,"En cours") | F11: =COUNTIFS(Suivi!$A$6:$A$70,"E7",Suivi!$F$6:$F$70,"À faire") | G11: =IFERROR(D11/C11,0)
A12: 8. Qualité de la remise | B12: 5 | C12: =COUNTIF(Suivi!$A$6:$A$70,"E8") | D12: =COUNTIFS(Suivi!$A$6:$A$70,"E8",Suivi!$F$6:$F$70,"Fait") | E12: =COUNTIFS(Suivi!$A$6:$A$70,"E8",Suivi!$F$6:$F$70,"En cours") | F12: =COUNTIFS(Suivi!$A$6:$A$70,"E8",Suivi!$F$6:$F$70,"À faire") | G12: =IFERROR(D12/C12,0)
A13: TOTAL | B13: =SUM(B5:B12) | C13: =SUM(C5:C12) | D13: =SUM(D5:D12) | E13: =SUM(E5:E12) | F13: =SUM(F5:F12) | G13: =IFERROR(D13/C13,0)
A15: Note : la colonne Points reprend la pondération de la grille d'évaluation de l'énoncé (total 100). L'étape 6 (tests et reproductibilité) n'a pas de points propres : elle est évaluée à travers « Qualité de la remise ».

Sheet Suivi
A1: TP1 – Base de données II (420-B56) – Suivi des tâches
A2: Base tp1_vincent_trudel · schéma commerce · cible de fin : 25 septembre 2026 (remise officielle : 16 octobre 2026)
A3: Mode d'emploi : ne modifiez que la colonne Statut (menu déroulant : À faire / En cours / Fait / Sans objet). Le reste se calcule tout seul dans l'onglet Tableau de bord.
A5: Code | B5: Étape | C5: Pts | D5: Jour prévu | E5: Tâche | F5: Statut | G5: Notes | H5: Type de décision
A6: E1 | B6: 1. Analyse et conception | C6: 15 | D6: 17-18 sept | E6: Décrire le besoin et les utilisateurs visés | F6: Fait
A7: E1 | B7: 1. Analyse et conception | C7: 15 | D7: 17-18 sept | E7: Rédiger 5 règles métier VÉRIFIABLES | F7: Fait | G7: Tableau dans Doc/Analyse et Conception.docx (18 sept) : stock, évaluation, expédition ≤ commandé, réception validée figée, stock augmenté à la validation. Chacune avec son déclencheur. 19 sept : 3 règles ajoutées (annulation) : commande jamais supprimée (annulée à la place); annulation permise seulement avant l'expédition (En attente, Payée, En préparation); commande annulée figée + stock rendu à l'annulation. À ajouter au tableau du docx. 22 sept : nouvelle règle à ajouter au docx — cycle de vie des statuts (ordre imposé; Payée exige un paiement complété couvrant le total; Expédiée/Livrée exigent expéditions couvrantes/complétées). | H7: Règle métier – déclencheur
A8: E1 | B8: 1. Analyse et conception | C8: 15 | D8: 17-18 sept | E8: Trancher : quelle colonne JSONB | F8: Fait | G8: Table séparée specification_produit (1-1 avec produit, UNIQUE id_produit, ON DELETE CASCADE). Forme du document encore à définir. | H8: Conception – JSONB
A9: E1 | B9: 1. Analyse et conception | C9: 15 | D9: 17-18 sept | E9: Trancher : réception de marchandise (UPDATE applicatif ou table reception) | F9: Fait | G9: Tables reception + info_reception. Créée attendue, validée via est_complete; déclencheur ajoute au stock. Validée = figée (BEFORE UPDATE/DELETE). Pas de champ archivé. | H9: Conception – schéma
A10: E1 | B10: 1. Analyse et conception | C10: 15 | D10: 17-18 sept | E10: Trancher : sujet du déclencheur d'audit | F10: Fait | G10: Changement de statut d'une commande (INSERT, UPDATE réel de id_statut, DELETE). Table spécifique sans FK, noms de statuts, current_user. Audit des réceptions écarté (peu de valeur). | H10: Conception – audit
A11: E1 | B11: 1. Analyse et conception | C11: 15 | D11: 17-18 sept | E11: Corriger le commentaire de produit dans 01_create_schema.sql | F11: Fait | G11: Commentaire corrigé : stock réel vs quantité prévisionnelle. | H11: Documentation
A12: E1 | B12: 1. Analyse et conception | C12: 15 | D12: 17-18 sept | E12: Trancher : info_expedition — UNIQUE (id_info_commande) pour « une ligne dans un seul colis » | F12: Fait | G12: Option 3 : une ligne peut être répartie sur plusieurs colis. quantite_expediee dans info_expedition + trg_valider_quantite_expediee et trg_proteger_quantite_commandee (validés le 18 sept). | H12: Conception – schéma
A13: E1 | B13: 1. Analyse et conception | C13: 15 | D13: 17-18 sept | E13: Trancher : booléen est_complete ou date seule (paiement, expedition, reception) | F13: Fait | G13: Booléen conservé partout, avec CHECK de cohérence. Redondance à justifier une fois dans la section 3FN. | H13: Conception – 3FN
A14: E1 | B14: 1. Analyse et conception | C14: 15 | D14: 17-18 sept | E14: Trancher : nomenclature (snake_case ou camelCase) | F14: Fait | G14: snake_case conservé (minuscules, sans accent; FK du même nom que la PK). Le camelCase exigerait des guillemets partout. | H14: Nomenclature
A15: E1 | B15: 1. Analyse et conception | C15: 15 | D15: 17-18 sept | E15: Diagramme ER : ≥ 8 entités, cardinalités, attributs (outil ERD de pgAdmin 4) | F15: En cours | G15: À refaire : il manque audit_statut_commande (14e table) et quantite_expediee dans info_expedition. Refaire le .pgerd + captures (l'export Download image n'affiche pas les liens). 19 sept : FK info_commande → commande n'a plus ON DELETE CASCADE. | H15: Livrable
A16: E1 | B16: 1. Analyse et conception | C16: 15 | D16: 17-18 sept | E16: Schéma relationnel + démonstration de la 3FN | F16: Fait | G16: Doc/Schema_relationnel_3FN.docx : 14 relations, 1FN/2FN/3FN, DF par table, valeurs figées, dénormalisations (quantite_totale_produit, est_complete), audit sans FK, répartition d'une ligne sur plusieurs colis. 19 sept : à mettre à jour — FK info_commande.id_commande sans ON DELETE CASCADE (une commande n'est jamais supprimée). | H16: Conception – 3FN
A17: E1 | B17: 1. Analyse et conception | C17: 15 | D17: 17-18 sept | E17: Dictionnaire de données : type, obligation, défaut, validation | F17: Fait | G17: Doc/Dictionnaire_donnees.docx : 14 tables + structure JSONB (à jour au 18 sept, quantite_expediee incluse). Relecture finale à l'étape 8. 19 sept : à mettre à jour — FK info_commande.id_commande sans cascade; valeurs de statut (6); nouvelles règles d'annulation. 25 sept : à mettre à jour — clés JSONB toutes facultatives (absente = sans objet, null = valeur inconnue).
A18: E1 | B18: 1. Analyse et conception | C18: 15 | D18: 17-18 sept | E18: Justifier le choix JSONB (variabilité ou structure imbriquée) | F18: Fait | G18: Rédigée le 18 sept (au « je ») : variabilité selon la catégorie, alternatives écartées (table par catégorie, champ par spécification), structure imbriquée, CHECK du noyau. À coller dans Analyse et Conception.docx. Le détail des CHECK et du GIN est dans le dictionnaire. 25 sept : à mettre à jour — plus aucune clé obligatoire, prévu d'avance pour de futurs prototypes / objets de collection (marque ou garantie parfois inconnues). | H18: Conception – JSONB
A19: E2 | B19: 2. Implémentation et JSONB | C19: 20 | D19: 19 sept | E19: Tables, PK, FK, NOT NULL, UNIQUE, CHECK, DEFAULT | F19: Fait | G19: 14 tables validées sur PostgreSQL 16 (18 sept, creer_bd.command sans erreur). | H19: Conception – schéma
A20: E2 | B20: 2. Implémentation et JSONB | C20: 20 | D20: 19 sept | E20: Ajouter ≥ 1 colonne JSONB (objet imbriqué ou tableau) | F20: Fait | G20: JSONB dans specification_produit : objet imbriqué (dimensions, ecran, materiel) + tableau (connectivite). Création validée le 18 sept. | H20: Conception – JSONB
A21: E2 | B21: 2. Implémentation et JSONB | C21: 20 | D21: 19 sept | E21: Contrainte validant une propriété essentielle du JSONB | F21: Fait | G21: 6 CHECK créés sans erreur (18 sept). Tests de refus prévus à l'étape 6. 25 sept : contraintes assouplies (choix de Vincent, option A) : aucune clé obligatoire, prévu pour de futurs prototypes / objets de collection. Chaque clé commune est absente, null ou du bon type. ck_spec_cles_obligatoires retirée, ck_spec_facultatifs fusionnée dans ck_spec_types; garantie ≥ 0 et connectivité non vide vérifiées seulement si fournies. Pas de prototype dans les données ni les tests pour l'instant. Validé par Vincent (creer_bd.command + tests OK). | H21: Contrainte
A22: E2 | B22: 2. Implémentation et JSONB | C22: 20 | D22: 19 sept | E22: Index GIN adapté à une requête JSONB | F22: Fait | G22: idx_specification_produit_gin (jsonb_path_ops, pour @>) créé. Démonstration EXPLAIN à l'étape 4. | H22: Index
A23: E2 | B23: 2. Implémentation et JSONB | C23: 20 | D23: 19 sept | E23: 3 index justifiés par des requêtes réelles | F23: Fait | G23: 4 index (18 sept) : commande(id_client), commande(date_commande), info_commande(id_produit), audit_statut_commande(id_commande, date_changement). Les PK et UNIQUE ne comptent pas. EXPLAIN ANALYZE à l'étape 4. | H23: Index
A24: E2 | B24: 2. Implémentation et JSONB | C24: 20 | D24: 19 sept | E24: Charger la table statut | F24: Fait | G24: 03_donnees.sql écrit le 19 sept : 6 statuts insérés en premier (En attente, Payée, En préparation, Expédiée, Livrée, Annulée). Exécuté et validé le 22 sept.
A25: E2 | B25: 2. Implémentation et JSONB | C25: 20 | D25: 19 sept | E25: Charger ≥ 250 enregistrements fictifs (≥ 100 dans une table centrale) | F25: Fait | G25: Insérer les évaluations APRÈS les commandes (déclencheur). Générer par script = reproductible. 19 sept : 03_donnees.sql écrit. Paramètres en haut (nb_clients, nb_commandes, graine); défaut 150 / 500 ≈ 5 000 lignes. Fixe : 6 catégories, 24 produits + JSONB, 12 réceptions. Relançable (TRUNCATE ... RESTART IDENTITY). Dates d'audit étalées (accepté). Exécuté et validé le 22 sept (creer_bd.command, étapes 0 à 3 sans erreur). 22 sept : 03 réorganisé pour le cycle de vie : par commande, lignes → paiement → expéditions → progression du statut EN DERNIER; commande sans ligne ramenée à En attente. Revalidé le 22 sept (creer_bd.command sans erreur).
A26: E2 | B26: 2. Implémentation et JSONB | C26: 20 | D26: 19 sept | E26: Régénérer le diagramme ERD après l'ajout du JSONB | F26: Fait | G26: Le JSONB a été ajouté avant la génération du diagramme (18 sept).
A27: E3 | B27: 3. Fonctions avancées | C27: 20 | D27: 20 sept | E27: Vues utiles à l'application ou au rapport (2 vues) | F27: Fait | G27: 22 sept : 2 vues décidées + 1 fonction. 04_vues_fonctions.sql écrit. v_commandes : id_commande, nom_client, date_commande, nom_statut (toutes les commandes, annulées comprises; pas de total). v_receptions_attendues : réceptions est_complete = FALSE, une ligne par réception, total d'unités attendues. Détail d'une réception = requête paramétrée dans l'app. Testées et validées par Vincent le 22 sept (v_commandes : compte = commande, Annulée présente; v_receptions_attendues : 3 lignes = réceptions non complétées, total réception 10 = SUM info_reception = 30). | H27: Livrable
A28: E3 | B28: 3. Fonctions avancées | C28: 20 | D28: 20 sept | E28: Une vue matérialisée + sa commande REFRESH | F28: Fait | G28: 22 sept : mv_ventes_produit_7j ajoutée à 04_vues_fonctions.sql. Une ligne par produit : id, nom, catégorie, prix, coût, stock, quantite_vendue_7j (7 derniers jours au moment du REFRESH, annulées exclues, 0 si aucune vente), date_rafraichissement. Index UNIQUE (id_produit) → REFRESH CONCURRENTLY. Refresh chaque nuit : documenté (cron 2 h, README/rapport) + job pgAgent créé par Vincent. Testée et validée le 22 sept. Job pgAgent refresh_mv_ventes_produits_7j (base postgres, step SQL local sur tp1_vincent_trudel, tous les jours 02:00) fonctionnel. Problème réglé : ~postgres/.pgpass (/Library/PostgreSQL/18) ne couvrait que la base postgres → champ base remplacé par *. À documenter dans README/rapport (cron en alternative; .pgpass jamais dans la remise). Serveur = PostgreSQL 18. | H28: Livrable
A29: E3 | B29: 3. Fonctions avancées | C29: 20 | D29: 20 sept | E29: Une fonction PL/pgSQL avec ≥ 1 paramètre | F29: Fait | G29: 22 sept : details_commande(p_id_commande) dans 04_vues_fonctions.sql. Retourne produit, quantite_commandee, prix_unitaire_fige (ajouté le 22 sept), sous_total (une ligne par produit). Pas de total : calculé par l'app. Commande inexistante → RAISE EXCEPTION SQLSTATE P0002. Commande sans ligne → résultat vide. Version initiale testée et validée le 22 sept (sous-total correct, exception P0002 OK); version avec prix unitaire retestée et validée le 22 sept.
A30: E3 | B30: 3. Fonctions avancées | C30: 20 | D30: 20 sept | E30: Une procédure PL/pgSQL en plusieurs étapes | F30: Fait | G30: 22 sept : avancer_commande(p_id_commande, p_camion DEFAULT NULL) dans 04_vues_fonctions.sql (remplace l'idée valider_reception). Passe au statut suivant et fait le travail de l'étape : En attente → Payée → En préparation (statut seul, le déclencheur vérifie le paiement); En préparation → Expédiée (crée expedition + info_expedition pour la quantité restante); Expédiée → Livrée (complète les expéditions). FOR UPDATE, atomique. Erreurs : inexistante (P0002), Livrée/Annulée. Limite : expédition partagée entre commandes. Testée et validée par Vincent le 22 sept (saut refusé, Payée sans paiement refusé, INSERT hors En attente refusé, parcours complet + audit + expédition, Livrée ne peut plus avancer, annulation OK). | H30: Livrable
A31: E3 | B31: 3. Fonctions avancées | C31: 20 | D31: 20 sept | E31: Table d'audit + déclencheur (opération, date, valeurs utiles) | F31: Fait | G31: audit_statut_commande (01) + trg_audit_statut_commande (02), créés sans erreur le 18 sept. Tests prévus à l'étape 6. 19 sept : branche DELETE conservée comme filet de sécurité (n'arrive plus, suppression de commande interdite). | H31: Conception – audit
A32: E3 | B32: 3. Fonctions avancées | C32: 20 | D32: 20 sept | E32: Rôle lecture + rôle modification, privilèges minimaux | F32: Fait | G32: 22 sept : 05_roles.sql. Personnel = rôles PostgreSQL, clients = application (hash_mot_passe_client); pas de table type de compte. Groupes NOLOGIN emboîtés : tp1_employe (CONNECT, USAGE, SELECT sauf client.hash_mot_passe_client, EXECUTE details_commande) → tp1_gestionnaire (+ INSERT/UPDATE tables d'opération + catalogue sauf statut, + INSERT audit, + EXECUTE avancer_commande) → tp1_admin (+ MAINTAIN). Aucun DELETE/TRUNCATE; droits de PUBLIC retirés. Utilisateurs demo_employe, demo_gestionnaire, demo_admin (CREATEROLE + ADMIN OPTION), sans mot de passe dans le script. Pas de SECURITY DEFINER (limite : fausse ligne d'audit possible). Testés et validés le 22 sept (SET ROLE). ⚠ À REVALIDER par Vincent et s'assurer de bien comprendre à quoi servent les rôles et chaque privilège. | H32: Sécurité
A33: E3 | B33: 3. Fonctions avancées | C33: 20 | D33: 20 sept | E33: Une transaction COMMIT + une ROLLBACK | F33: Fait | G33: 22 sept : 06_transactions.sql (hors creer_bd.command : modifie les données et le 2e scénario échoue volontairement; à exécuter bloc par bloc dans le MÊME onglet pgAdmin, table temporaire). Scénario carte : autorisation (est_complete = FALSE) puis capture (TRUE + date). Processeur externe simulé, réponse en commentaire; l'app (étape 5) décidera du COMMIT/ROLLBACK. 1) Capture approuvée → paiement complété + commande Payée → COMMIT. 2) Autorisation partielle (moitié) → capture puis passage à Payée refusé par trg_proteger_commande (règle g) → ROLLBACK : paiement revenu en autorisation, commande En attente, aucune ligne d'audit. Règle protégée : pas de commande payée sans paiement suffisant + tout ou rien. Testé et validé par Vincent le 22 sept : scénario 1 (COMMIT) OK, scénario 2 (erreur attendue puis ROLLBACK) OK. À exécuter en 3 temps : 2.1+2.2, puis 2.3 sans le ROLLBACK, puis le ROLLBACK seul (une erreur annule tout l'envoi, y compris l'INSERT dans la table temporaire). | H33: Livrable
A34: E3 | B34: 3. Fonctions avancées | C34: 20 | D34: 20 sept | E34: Déclencheurs métier (stock, évaluation, réception, expédition, annulation) | F34: Fait | G34: 11 déclencheurs : stock, évaluation, réception x3, audit, quantité expédiée x2 (installés sans erreur le 18 sept) + annulation x3 écrits le 19 sept (trg_proteger_commande, trg_restituer_stock_annulation, trg_proteger_lignes_commande_annulee) — exécutés sans erreur le 22 sept. Tests prévus à l'étape 6. 22 sept : trg_proteger_commande étendu (BEFORE INSERT/UPDATE/DELETE) — cycle de vie : INSERT toujours En attente; transitions permises seulement En attente → Payée → En préparation → Expédiée → Livrée (+ annulation); Payée = ≥1 ligne + paiements complétés ≥ total; Expédiée = quantités couvertes par info_expedition; Livrée = expéditions complétées. Revalidé le 22 sept. | H34: Règle métier – déclencheur
A35: E4 | B35: 4. Requêtes et performance | C35: 20 | D35: 21 sept | E35: Requête : jointure d'au moins 3 tables | F35: Fait | G35: 22 sept : requête 1 dans 07_requetes.sql (produit JOIN categorie JOIN specification_produit, infos produit + nom_categorie + specifications_produit JSONB). Validée par Vincent le 22 sept.
A36: E4 | B36: 4. Requêtes et performance | C36: 20 | D36: 21 sept | E36: Requête : agrégation GROUP BY + HAVING | F36: Fait | G36: 24 sept : requête 2 dans 07_requetes.sql (revenu total par catégorie, commandes non annulées, GROUP BY + HAVING sur un seuil de 1000). Validée par Vincent le 24 sept.
A37: E4 | B37: 4. Requêtes et performance | C37: 20 | D37: 21 sept | E37: Requête : sous-requête corrélée ou EXISTS | F37: Fait | G37: 24 sept : requête 3 dans 07_requetes.sql (client(s) ayant le plus dépensé, commandes non annulées, via NOT EXISTS corrélé sur deux sous-requêtes dérivées du total par client). Validée par Vincent le 24 sept.
A38: E4 | B38: 4. Requêtes et performance | C38: 20 | D38: 21 sept | E38: Requête : expression de table commune (WITH) | F38: Fait | G38: 24 sept : requête 4 dans 07_requetes.sql (CTE commande_totaux : total + nb de produits différents par commande, non annulées; requête principale agrège par client : nb commandes, 1re/dernière date, total dépensé, moyenne de produits différents par commande). Validée par Vincent le 24 sept.
A39: E4 | B39: 4. Requêtes et performance | C39: 20 | D39: 21 sept | E39: Requête : fonction de fenêtre (OVER) | F39: Fait | G39: 24 sept : requête 5 dans 07_requetes.sql (classement complet des clients par montant dépensé, commandes non annulées, RANK() OVER (ORDER BY SUM(...) DESC) directement sur l'agrégat groupé — reprend la question de la requête 3 avec la technique fenêtre; le rang 1 doit correspondre au client trouvé par NOT EXISTS en requête 3). Validée par Vincent le 24 sept.
A40: E4 | B40: 4. Requêtes et performance | C40: 20 | D40: 21 sept | E40: Requête : UNION, INTERSECT ou EXCEPT | F40: Fait | G40: 24 sept : requête 6 dans 07_requetes.sql (clients "à risque" : UNION entre commande annulée et commande annulée avec paiement non complété; limité aux commandes déjà annulées car le schéma paiement n'a pas de colonne statut/raison pour distinguer échoué de pas encore complété — voir question ouverte #3 dans les notes de suivi). Validée par Vincent le 24 sept.
A41: E4 | B41: 4. Requêtes et performance | C41: 20 | D41: 21 sept | E41: Requête : appel à la vue, la vue matérialisée ou la fonction | F41: Fait | G41: 24 sept : requête 7 dans 07_requetes.sql (top 10 produits vendus dans les 7 derniers jours, à partir de la vue matérialisée mv_ventes_produit_7j, filtrée sur quantite_vendue_7j > 0, triée décroissant). Validée par Vincent le 24 sept.
...

Sheet Calendrier
A1: Calendrier cible – 17 au 25 septembre 2026
A2: Estimations discutées. Marge : le jour gagné en combinant le 17 et le 18, plus la semaine du 28 au besoin.
A4: Jour | B4: Objectif | C4: Estimation sans IA | D4: Estimation avec IA
A5: Jeu 17 + Ven 18 | B5: Étape 1 au complet : règles métier, décisions ouvertes, diagramme ERD, 3FN, dictionnaire | C5: 3 h - 4 h 30 | D5: 2 h - 3 h
A6: Sam 19 | B6: Étape 2 : JSONB + contrainte + GIN, charger statut, 250 enregistrements | C6: 2 h 30 - 3 h 30 | D6: 1 h 15 - 1 h 45
A7: Dim 20 | B7: Étape 3 : vue, vue matérialisée, fonction, procédure, audit, rôles, transactions | C7: 3 h - 4 h | D7: 1 h 30 - 2 h 30
A8: Lun 21 | B8: Étape 4 : les 10 requêtes | C8: 2 h 30 - 3 h 30 | D8: 1 h 30 - 2 h
A9: Mar 22 | B9: Étape 4 : index + EXPLAIN ANALYZE · Étape 6 : tests | C9: à estimer | D9: à estimer
A10: Mer 23 | B10: Étape 5 : application cliente | C10: à estimer | D10: à estimer
A11: Jeu 24 | B11: Étape 7 : export + fiche de données · README | C11: à estimer | D11: à estimer
A12: Ven 25 | B12: Étape 8 : rapport.pdf, IA.md, archive, vérification finale | C12: à estimer | D12: à estimer
A14: Total des 4 premiers blocs : 11 h - 15 h 30 sans IA, 6 h 30 - 9 h 30 avec l'aide de l'IA pour le code.
A15: Rappel : l'énoncé annonce ~10 h pour le TP complet, ce qui est optimiste. Prévoir plutôt 20 à 25 h au total.
A16: La part irréductible est la vérification : l'énoncé exige de pouvoir expliquer, tester et modifier chaque élément remis en direct.
